Workbook

Sheet BS
A1: 帳票名：残高試算表(年間推移)
A3: 事業所名：株式会社マザースマイル
A4: 税抜/税込：税抜
A6: 勘定科目 | B6: =VLOOKUP(A6,Sheet1!$A$1:$B$242,2,FALSE) -> 계정과목 | C6: 4月度 | D6: 5月度 | E6: 6月度 | F6: 7月度 | G6: 8月度 | H6: 9月度 | I6: 上半期残高(合計) | J6: 10月度 | K6: 11月度 | L6: 12月度 | M6: 1月度 | N6: 2月度 | O6: 3月度 | P6: 下半期残高(合計) | Q6: 当期仮残高(合計) | R6: 決算残高(合計) | S6: 当期残高(合計)
A7: [現金･預金] | B7: =VLOOKUP(A7,Sheet1!$A$1:$B$242,2,FALSE) -> [현금･예금]
A8: 現金 | B8: =VLOOKUP(A8,Sheet1!$A$1:$B$242,2,FALSE) -> 현금 | C8: 129534 | D8: 80197 | E8: 252530 | F8: 228130 | G8: 254588 | H8: 98075 | I8: 98075 | J8: 220062 | K8: 19207 | L8: 413805 | M8: 413805 | N8: 413805 | O8: 413805 | P8: 413805 | Q8: 413805 | R8: 413805 | S8: 413805
A9: 普通預金 | B9: =VLOOKUP(A9,Sheet1!$A$1:$B$242,2,FALSE) -> 보통예금 | C9: 13780845 | D9: 10920496 | E9: 16156649 | F9: 22398432 | G9: 30896250 | H9: 24328317 | I9: 24328317 | J9: 41514483 | K9: 46556239 | L9: 49866189 | M9: 49866189 | N9: 49866189 | O9: 49866189 | P9: 49866189 | Q9: 49866189 | R9: 49866189 | S9: 49866189
A10: 現金･預金合計 | B10: =VLOOKUP(A10,Sheet1!$A$1:$B$242,2,FALSE) -> 현금 ･예금합계 | C10: 13910379 | D10: 11000693 | E10: 16409179 | F10: 22626562 | G10: 31150838 | H10: 24426392 | I10: 24426392 | J10: 41734545 | K10: 46575446 | L10: 50279994 | M10: 50279994 | N10: 50279994 | O10: 50279994 | P10: 50279994 | Q10: 50279994 | R10: 50279994 | S10: 50279994
A11: [売上債権] | B11: =VLOOKUP(A11,Sheet1!$A$1:$B$242,2,FALSE) -> [매출채권]
A12: 売掛金 | B12: =VLOOKUP(A12,Sheet1!$A$1:$B$242,2,FALSE) -> 외상매출금 | C12: 16474507 | D12: 18116551 | E12: 25087039 | F12: 22265770 | G12: 20381384 | H12: 35647802 | I12: 35647802 | J12: 26503906 | K12: 33157239 | L12: 50784726 | M12: 50784726 | N12: 50784726 | O12: 50784726 | P12: 50784726 | Q12: 50784726 | R12: 50784726 | S12: 50784726
A13: 貸倒引当金(売) | B13: =VLOOKUP(A13,Sheet1!$A$1:$B$242,2,FALSE) -> 대손충당금 | C13: -206241 | D13: -206241 | E13: -206241 | F13: -206241 | G13: -206241 | H13: -206241 | I13: -206241 | J13: -206241 | K13: -206241 | L13: -507847 | M13: -507847 | N13: -507847 | O13: -507847 | P13: -507847 | Q13: -507847 | R13: -507847 | S13: -507847
A14: 売上債権合計 | B14: =VLOOKUP(A14,Sheet1!$A$1:$B$242,2,FALSE) -> 매출채권합계 | C14: 16268266 | D14: 17910310 | E14: 24880798 | F14: 22059529 | G14: 20175143 | H14: 35441561 | I14: 35441561 | J14: 26297665 | K14: 32950998 | L14: 50276879 | M14: 50276879 | N14: 50276879 | O14: 50276879 | P14: 50276879 | Q14: 50276879 | R14: 50276879 | S14: 50276879
A15: [有価証券] | B15: =VLOOKUP(A15,Sheet1!$A$1:$B$242,2,FALSE) -> [유가증권]
A16: 有価証券合計 | B16: =VLOOKUP(A16,Sheet1!$A$1:$B$242,2,FALSE) -> 유가증권합계 | C16: 0 | D16: 0 | E16: 0 | F16: 0 | G16: 0 | H16: 0 | I16: 0 | J16: 0 | K16: 0 | L16: 0 | M16: 0 | N16: 0 | O16: 0 | P16: 0 | Q16: 0 | R16: 0 | S16: 0
A17: [棚卸資産] | B17: =VLOOKUP(A17,Sheet1!$A$1:$B$242,2,FALSE) -> [재고자산]
A18: 商品 | B18: =VLOOKUP(A18,Sheet1!$A$1:$B$242,2,FALSE) -> 상품 | C18: 75443317 | D18: 72214523 | E18: 63829945 | F18: 68176813 | G18: 67522901 | H18: 47297814 | I18: 47297814 | J18: 58667847 | K18: 61842456 | L18: 72632874 | M18: 72632874 | N18: 72632874 | O18: 72632874 | P18: 72632874 | Q18: 72632874 | R18: 72632874 | S18: 72632874
A19: 棚卸資産合計 | B19: =VLOOKUP(A19,Sheet1!$A$1:$B$242,2,FALSE) -> 재고자산합계 | C19: 75443317 | D19: 72214523 | E19: 63829945 | F19: 68176813 | G19: 67522901 | H19: 47297814 | I19: 47297814 | J19: 58667847 | K19: 61842456 | L19: 72632874 | M19: 72632874 | N19: 72632874 | O19: 72632874 | P19: 72632874 | Q19: 72632874 | R19: 72632874 | S19: 72632874
A20: [他流動資産] | B20: =VLOOKUP(A20,Sheet1!$A$1:$B$242,2,FALSE) -> [기타유동자산]
A21: 前渡金 | B21: =VLOOKUP(A21,Sheet1!$A$1:$B$242,2,FALSE) -> 전도금 | C21: 270000 | D21: 270000 | E21: 4444616 | F21: 225000 | G21: 225000 | H21: 11610396 | I21: 11610396 | J21: 5398138 | K21: 217300 | L21: 14379902 | M21: 14379902 | N21: 14379902 | O21: 14379902 | P21: 14379902 | Q21: 14379902 | R21: 14379902 | S21: 14379902
A22: 立替金 | B22: =VLOOKUP(A22,Sheet1!$A$1:$B$242,2,FALSE) -> 대지급금 | C22: 906748 | D22: 453374 | E22: 0 | F22: 0 | G22: 0 | H22: 0 | I22: 0 | J22: 0 | K22: 0 | L22: 0 | M22: 0 | N22: 0 | O22: 0 | P22: 0 | Q22: 0 | R22: 0 | S22: 0
A23: 前払費用 | B23: =VLOOKUP(A23,Sheet1!$A$1:$B$242,2,FALSE) -> 선급비용 | C23: 2194113 | D23: 2542344 | E23: 2569579 | F23: 2489570 | G23: 2448609 | H23: 2485724 | I23: 2485724 | J23: 2914357 | K23: 2062663 | L23: 1804553 | M23: 1804553 | N23: 1804553 | O23: 1804553 | P23: 1804553 | Q23: 1804553 | R23: 1804553 | S23: 1804553
A24: 未収入金 | B24: =VLOOKUP(A24,Sheet1!$A$1:$B$242,2,FALSE) -> 미수입금 | C24: 29802 | D24: 29802 | E24: 105432 | F24: 346774 | G24: 588118 | H24: 588742 | I24: 588742 | J24: 1712920 | K24: 916370 | L24: 309210 | M24: 309210 | N24: 309210 | O24: 309210 | P24: 309210 | Q24: 309210 | R24: 309210 | S24: 309210
A25: 仮払金 | B25: =VLOOKUP(A25,Sheet1!$A$1:$B$242,2,FALSE) -> 가불금 | C25: 0 | D25: 600000 | E25: 0 | F25: 0 | G25: 0 | H25: 3412100 | I25: 3412100 | J25: 3412100 | K25: 3412100 | L25: 0 | M25: 0 | N25: 0 | O25: 0 | P25: 0 | Q25: 0 | R25: 0 | S25: 0
A26: 仮払消費税等 | B26: =VLOOKUP(A26,Sheet1!$A$1:$B$242,2,FALSE) -> 가불소비세등 | C26: 2268151 | D26: 4056893 | E26: 6060352 | F26: 9067690 | G26: 11286037 | H26: 13209136 | I26: 13209136 | J26: 17574794 | K26: 21851603 | L26: 0 | M26: 0 | N26: 0 | O26: 0 | P26: 0 | Q26: 0 | R26: 0 | S26: 0
A27: 他流動資産合計 | B27: =VLOOKUP(A27,Sheet1!$A$1:$B$242,2,FALSE) -> 기타유동자산합계 | C27: 5668814 | D27: 7952413 | E27: 13179979 | F27: 12129034 | G27: 14547764 | H27: 31306098 | I27: 31306098 | J27: 31012309 | K27: 28460036 | L27: 16493665 | M27: 16493665 | N27: 16493665 | O27: 16493665 | P27: 16493665 | Q27: 16493665 | R27: 16493665 | S27: 16493665
A28: 流動資産合計 | B28: =VLOOKUP(A28,Sheet1!$A$1:$B$242,2,FALSE) -> 유동자산합계 | C28: 111290776 | D28: 109077939 | E28: 118299901 | F28: 124991938 | G28: 133396646 | H28: 138471865 | I28: 138471865 | J28: 157712366 | K28: 169828936 | L28: 189683412 | M28: 189683412 | N28: 189683412 | O28: 189683412 | P28: 189683412 | Q28: 189683412 | R28: 189683412 | S28: 189683412
A29: [有形固定資産] | B29: =VLOOKUP(A29,Sheet1!$A$1:$B$242,2,FALSE) -> [유형고정자산]
A30: 車両運搬具 | B30: =VLOOKUP(A30,Sheet1!$A$1:$B$242,2,FALSE) -> 차량운반구 | C30: 28073153 | D30: 28073153 | E30: 28073153 | F30: 28073153 | G30: 28073153 | H30: 28073153 | I30: 28073153 | J30: 26196619 | K30: 26196619 | L30: 26196619 | M30: 26196619 | N30: 26196619 | O30: 26196619 | P30: 26196619 | Q30: 26196619 | R30: 26196619 | S30: 26196619
A31: 工具器具備品 | B31: =VLOOKUP(A31,Sheet1!$A$1:$B$242,2,FALSE) -> 공구기구비품 | C31: 677164 | D31: 677164 | E31: 677164 | F31: 677164 | G31: 677164 | H31: 677164 | I31: 677164 | J31: 677164 | K31: 677164 | L31: 677164 | M31: 677164 | N31: 677164 | O31: 677164 | P31: 677164 | Q31: 677164 | R31: 677164 | S31: 677164
A32: 一括償却資産 | B32: =VLOOKUP(A32,Sheet1!$A$1:$B$242,2,FALSE) -> 일괄상각자산 | C32: 133722 | D32: 133722 | E32: 133722 | F32: 133722 | G32: 133722 | H32: 133722 | I32: 133722 | J32: 133722 | K32: 133722 | L32: 33431 | M32: 33431 | N32: 33431 | O32: 33431 | P32: 33431 | Q32: 33431 | R32: 33431 | S32: 33431
A33: 減価償却累計額 | B33: =VLOOKUP(A33,Sheet1!$A$1:$B$242,2,FALSE) -> 감가상각누계액 | C33: -20741624 | D33: -20978378 | E33: -21215132 | F33: -21451886 | G33: -21688640 | H33: -21925394 | I33: -21925394 | J33: -20285615 | K33: -20522369 | L33: -20759138 | M33: -20759138 | N33: -20759138 | O33: -20759138 | P33: -20759138 | Q33: -20759138 | R33: -20759138 | S33: -20759138
A34: 有形固定資産計 | B34: =VLOOKUP(A34,Sheet1!$A$1:$B$242,2,FALSE) -> 유형고정자산계 | C34: 8142415 | D34: 7905661 | E34: 7668907 | F34: 7432153 | G34: 7195399 | H34: 6958645 | I34: 6958645 | J34: 6721890 | K34: 6485136 | L34: 6148076 | M34: 6148076 | N34: 6148076 | O34: 6148076 | P34: 6148076 | Q34: 6148076 | R34: 6148076 | S34: 6148076
A35: [無形固定資産] | B35: =VLOOKUP(A35,Sheet1!$A$1:$B$242,2,FALSE) -> [무형고정자산]
A36: 無形固定資産計 | B36: =VLOOKUP(A36,Sheet1!$A$1:$B$242,2,FALSE) -> 무형고정자산계 | C36: 0 | D36: 0 | E36: 0 | F36: 0 | G36: 0 | H36: 0 | I36: 0 | J36: 0 | K36: 0 | L36: 0 | M36: 0 | N36: 0 | O36: 0 | P36: 0 | Q36: 0 | R36: 0 | S36: 0
A37: [投資その他の資産] | B37: =VLOOKUP(A37,Sheet1!$A$1:$B$242,2,FALSE) -> [투자기타자산]
A38: 差入保証金 | B38: =VLOOKUP(A38,Sheet1!$A$1:$B$242,2,FALSE) -> 차입보증금 | C38: 4658940 | D38: 4658940 | E38: 4658940 | F38: 4658940 | G38: 4702740 | H38: 4702740 | I38: 4702740 | J38: 6836046 | K38: 4436046 | L38: 4436046 | M38: 4436046 | N38: 4436046 | O38: 4436046 | P38: 4436046 | Q38: 4436046 | R38: 4436046 | S38: 4436046
A39: 長期貸付金 | B39: =VLOOKUP(A39,Sheet1!$A$1:$B$242,2,FALSE) -> 장기대여금 | C39: 1000000 | D39: 1000000 | E39: 1000000 | F39: 1000000 | G39: 1000000 | H39: 1000000 | I39: 1000000 | J39: 1000000 | K39: 1000000 | L39: 8828000 | M39: 8828000 | N39: 8828000 | O39: 8828000 | P39: 8828000 | Q39: 8828000 | R39: 8828000 | S39: 8828000
A40: 長期前払費用 | B40: =VLOOKUP(A40,Sheet1!$A$1:$B$242,2,FALSE) -> 장기선불비용 | C40: 1393195 | D40: 1393195 | E40: 1393195 | F40: 1393195 | G40: 1393195 | H40: 1393195 | I40: 1393195 | J40: 1393195 | K40: 637368 | L40: 401500 | M40: 401500 | N40: 401500 | O40: 401500 | P40: 401500 | Q40: 401500 | R40: 401500 | S40: 401500
A41: リサイクル預託金 | B41: =VLOOKUP(A41,Sheet1!$A$1:$B$242,2,FALSE) -> 리사이클 예탁금 | C41: 67070 | D41: 67070 | E41: 67070 | F41: 67070 | G41: 67070 | H41: 67070 | I41: 67070 | J41: 58520 | K41: 58520 | L41: 58520 | M41: 58520 | N41: 58520 | O41: 58520 | P41: 58520 | Q41: 58520 | R41: 58520 | S41: 58520
A42: 投資その他の資産合計 | B42: =VLOOKUP(A42,Sheet1!$A$1:$B$242,2,FALSE) -> 투자기타자산합계 | C42: 7119205 | D42: 7119205 | E42: 7119205 | F42: 7119205 | G42: 7163005 | H42: 7163005 | I42: 7163005 | J42: 9287761 | K42: 6131934 | L42: 13724066 | M42: 13724066 | N42: 13724066 | O42: 13724066 | P42: 13724066 | Q42: 13724066 | R42: 13724066 | S42: 13724066
...

Sheet PL
A1: 帳票名：残高試算表(年間推移)
A3: 事業所名：株式会社マザースマイル
A4: 税抜/税込：税抜
A6: 勘定科目 | B6: =VLOOKUP(A6,Sheet1!$A$1:$B$242,2,FALSE) -> 계정과목 | C6: 4月度 | D6: 5月度 | E6: 6月度 | F6: 7月度 | G6: 8月度 | H6: 9月度 | I6: 上半期残高(合計) | J6: 10月度 | K6: 11月度 | L6: 12月度 | M6: 1月度 | N6: 2月度 | O6: 3月度 | P6: 下半期残高(合計) | Q6: 当期仮残高(合計) | R6: 決算残高(合計) | S6: 当期残高(合計)
A7: [売上高] | B7: =VLOOKUP(A7,Sheet1!$A$1:$B$242,2,FALSE) -> [매출]
A8: 売上高 | B8: =VLOOKUP(A8,Sheet1!$A$1:$B$242,2,FALSE) -> 매출 | C8: 33690019 | D8: 35539299 | E8: 49636275 | F8: 42213072 | G8: 38221057 | H8: 62293873 | I8: 261593595 | J8: 55454255 | K8: 60410575 | L8: 97751542 | M8: 0 | N8: 0 | O8: 0 | P8: 213616372 | Q8: 475209967 | R8: 0 | S8: 475209967
A9: 売上戻り高 | B9: =VLOOKUP(A9,Sheet1!$A$1:$B$242,2,FALSE) -> 매출환입 | C9: 398597 | D9: 263602 | E9: 179902 | F9: 245075 | G9: 116290 | H9: 186517 | I9: 1389983 | J9: 238452 | K9: 259314 | L9: 366735 | M9: 0 | N9: 0 | O9: 0 | P9: 864501 | Q9: 2254484 | R9: 0 | S9: 2254484
A10: 売上高合計 | B10: =VLOOKUP(A10,Sheet1!$A$1:$B$242,2,FALSE) -> 매출합계 | C10: 33291422 | D10: 35275697 | E10: 49456373 | F10: 41967997 | G10: 38104767 | H10: 62107356 | I10: 260203612 | J10: 55215803 | K10: 60151261 | L10: 97384807 | M10: 0 | N10: 0 | O10: 0 | P10: 212751871 | Q10: 472955483 | R10: 0 | S10: 472955483
A11: [売上原価] | B11: =VLOOKUP(A11,Sheet1!$A$1:$B$242,2,FALSE) -> [매출원가]
A12: 期首商品棚卸高 | B12: =VLOOKUP(A12,Sheet1!$A$1:$B$242,2,FALSE) -> 기초상품재고액 | C12: 72910492 | D12: 75443317 | E12: 72214523 | F12: 63829945 | G12: 68176813 | H12: 67522901 | I12: 420097991 | J12: 47297814 | K12: 58667847 | L12: -453153160 | M12: 0 | N12: 0 | O12: 0 | P12: -347187499 | Q12: 72910492 | R12: 0 | S12: 72910492
A13: 期首商品棚卸高 | B13: =VLOOKUP(A13,Sheet1!$A$1:$B$242,2,FALSE) -> 기초상품재고액 | C13: 72910492 | D13: 75443317 | E13: 72214523 | F13: 63829945 | G13: 68176813 | H13: 67522901 | I13: 420097991 | J13: 47297814 | K13: 58667847 | L13: -453153160 | M13: 0 | N13: 0 | O13: 0 | P13: -347187499 | Q13: 72910492 | R13: 0 | S13: 72910492
A14: 仕入高 | B14: =VLOOKUP(A14,Sheet1!$A$1:$B$242,2,FALSE) -> 매입 | C14: 16061711 | D14: 10191346 | E14: 12106070 | F14: 21140128 | G14: 13143000 | H14: 8817768 | I14: 81460023 | J14: 32489688 | K14: 29002842 | L14: 36781672 | M14: 0 | N14: 0 | O14: 0 | P14: 98274202 | Q14: 179734225 | R14: 0 | S14: 179734225
A15: 仕入諸掛費 | B15: =VLOOKUP(A15,Sheet1!$A$1:$B$242,2,FALSE) -> 매입제비용 | C15: 1476872 | D15: 1121690 | E15: 1143317 | F15: 1235990 | G15: 1326417 | H15: 977990 | I15: 7282276 | J15: 2348382 | K15: 2926291 | L15: 3139535 | M15: 0 | N15: 0 | O15: 0 | P15: 8414208 | Q15: 15696484 | R15: 0 | S15: 15696484
A16: 当期商品仕入高 | B16: =VLOOKUP(A16,Sheet1!$A$1:$B$242,2,FALSE) -> 당기상품매입액 | C16: 17538583 | D16: 11313036 | E16: 13249387 | F16: 22376118 | G16: 14469417 | H16: 9795758 | I16: 88742299 | J16: 34838070 | K16: 31929133 | L16: 39921207 | M16: 0 | N16: 0 | O16: 0 | P16: 106688410 | Q16: 195430709 | R16: 0 | S16: 195430709
A17: 合計 | B17: =VLOOKUP(A17,Sheet1!$A$1:$B$242,2,FALSE) -> 합계 | C17: 90449075 | D17: 86756353 | E17: 85463910 | F17: 86206063 | G17: 82646230 | H17: 77318659 | I17: 508840290 | J17: 82135884 | K17: 90596980 | L17: -413231953 | M17: 0 | N17: 0 | O17: 0 | P17: -240499089 | Q17: 268341201 | R17: 0 | S17: 268341201
A18: 他勘定振替高(商) | B18: =VLOOKUP(A18,Sheet1!$A$1:$B$242,2,FALSE) -> 타계정전환 | C18: 348345 | D18: 312040 | E18: 203213 | F18: 321465 | G18: 332494 | H18: 398587 | I18: 1916144 | J18: 613306 | K18: 590023 | L18: 510941 | M18: 0 | N18: 0 | O18: 0 | P18: 1714270 | Q18: 3630414 | R18: 0 | S18: 3630414
A19: 期末商品棚卸高 | B19: =VLOOKUP(A19,Sheet1!$A$1:$B$242,2,FALSE) -> 기말상품재고액 | C19: 75443317 | D19: 72214523 | E19: 63829945 | F19: 68176813 | G19: 67522901 | H19: 47297814 | I19: 394485313 | J19: 58667847 | K19: 61842456 | L19: -442362742 | M19: 0 | N19: 0 | O19: 0 | P19: -321852439 | Q19: 72632874 | R19: 0 | S19: 72632874
A20: 期末商品棚卸高 | B20: =VLOOKUP(A20,Sheet1!$A$1:$B$242,2,FALSE) -> 기말상품재고액 | C20: 75443317 | D20: 72214523 | E20: 63829945 | F20: 68176813 | G20: 67522901 | H20: 47297814 | I20: 394485313 | J20: 58667847 | K20: 61842456 | L20: -442362742 | M20: 0 | N20: 0 | O20: 0 | P20: -321852439 | Q20: 72632874 | R20: 0 | S20: 72632874
A21: 売上原価 | B21: =VLOOKUP(A21,Sheet1!$A$1:$B$242,2,FALSE) -> 매출원가 | C21: 14657413 | D21: 14229790 | E21: 21430752 | F21: 17707785 | G21: 14790835 | H21: 29622258 | I21: 112438833 | J21: 22854731 | K21: 28164501 | L21: 28619848 | M21: 0 | N21: 0 | O21: 0 | P21: 79639080 | Q21: 192077913 | R21: 0 | S21: 192077913
A22: 売上総損益金額 | B22: =VLOOKUP(A22,Sheet1!$A$1:$B$242,2,FALSE) -> 매출총손익금액 | C22: 18634009 | D22: 21045907 | E22: 28025621 | F22: 24260212 | G22: 23313932 | H22: 32485098 | I22: 147764779 | J22: 32361072 | K22: 31986760 | L22: 68764959 | M22: 0 | N22: 0 | O22: 0 | P22: 133112791 | Q22: 280877570 | R22: 0 | S22: 280877570
A23: [販売管理費] | B23: =VLOOKUP(A23,Sheet1!$A$1:$B$242,2,FALSE) -> [판매관리비]
A24: 役員報酬 | B24: =VLOOKUP(A24,Sheet1!$A$1:$B$242,2,FALSE) -> 임원보수 | C24: 3998480 | D24: 3571440 | E24: 3571432 | F24: 3571432 | G24: 3571432 | H24: 3571432 | I24: 21855648 | J24: 3571432 | K24: 3571440 | L24: 3571432 | M24: 0 | N24: 0 | O24: 0 | P24: 10714304 | Q24: 32569952 | R24: 0 | S24: 32569952
A25: 給料手当 | B25: =VLOOKUP(A25,Sheet1!$A$1:$B$242,2,FALSE) -> 급여수당 | C25: 3163971 | D25: 2559049 | E25: 2364237 | F25: 3244017 | G25: 2913737 | H25: 2985857 | I25: 17230868 | J25: 3175237 | K25: 3405637 | L25: 3480263 | M25: 0 | N25: 0 | O25: 0 | P25: 10061137 | Q25: 27292005 | R25: 0 | S25: 27292005
A26: 雑給 | B26: =VLOOKUP(A26,Sheet1!$A$1:$B$242,2,FALSE) -> 잡급 | C26: 0 | D26: 0 | E26: 129000 | F26: 0 | G26: 217000 | H26: 0 | I26: 346000 | J26: 0 | K26: 241000 | L26: 230000 | M26: 0 | N26: 0 | O26: 0 | P26: 471000 | Q26: 817000 | R26: 0 | S26: 817000
A27: 賞与 | B27: =VLOOKUP(A27,Sheet1!$A$1:$B$242,2,FALSE) -> 상여 | C27: 253740 | D27: 0 | E27: 0 | F27: 0 | G27: 2249854 | H27: 0 | I27: 2503594 | J27: 210422 | K27: 0 | L27: 0 | M27: 0 | N27: 0 | O27: 0 | P27: 210422 | Q27: 2714016 | R27: 0 | S27: 2714016
A28: 法定福利費 | B28: =VLOOKUP(A28,Sheet1!$A$1:$B$242,2,FALSE) -> 법정복리비 | C28: 739876 | D28: 615470 | E28: 583595 | F28: 626960 | G28: 655710 | H28: 1089194 | I28: 4310805 | J28: 555901 | K28: 766589 | L28: 647031 | M28: 0 | N28: 0 | O28: 0 | P28: 1969521 | Q28: 6280326 | R28: 0 | S28: 6280326
A29: 福利厚生費 | B29: =VLOOKUP(A29,Sheet1!$A$1:$B$242,2,FALSE) -> 복리후생비 | C29: 0 | D29: 0 | E29: 18000 | F29: 4802 | G29: 0 | H29: 0 | I29: 22802 | J29: 18000 | K29: 8889 | L29: 521308 | M29: 0 | N29: 0 | O29: 0 | P29: 548197 | Q29: 570999 | R29: 0 | S29: 570999
A30: 外注費 | B30: =VLOOKUP(A30,Sheet1!$A$1:$B$242,2,FALSE) -> 외주비 | C30: 936289 | D30: 1715717 | E30: 1401132 | F30: 566904 | G30: 578000 | H30: 381400 | I30: 5579442 | J30: 445000 | K30: 421040 | L30: 477000 | M30: 0 | N30: 0 | O30: 0 | P30: 1343040 | Q30: 6922482 | R30: 0 | S30: 6922482
A31: 荷造運賃 | B31: =VLOOKUP(A31,Sheet1!$A$1:$B$242,2,FALSE) -> 운반비 | C31: 2119024 | D31: 1964961 | E31: 1987110 | F31: 1984855 | G31: 1725344 | H31: 2799677 | I31: 12580971 | J31: 2162415 | K31: 2374825 | L31: 3220352 | M31: 0 | N31: 0 | O31: 0 | P31: 7757592 | Q31: 20338563 | R31: 0 | S31: 20338563
A32: 広告宣伝費 | B32: =VLOOKUP(A32,Sheet1!$A$1:$B$242,2,FALSE) -> 광고선전비 | C32: 406744 | D32: 422827 | E32: 251962 | F32: 354093 | G32: 383164 | H32: 495154 | I32: 2313944 | J32: 704554 | K32: 1008552 | L32: 857523 | M32: 0 | N32: 0 | O32: 0 | P32: 2570629 | Q32: 4884573 | R32: 0 | S32: 4884573
A33: 交際費 | B33: =VLOOKUP(A33,Sheet1!$A$1:$B$242,2,FALSE) -> 교제비 | C33: 17828 | D33: 87433 | E33: 157134 | F33: 146220 | G33: 124059 | H33: 59884 | I33: 592558 | J33: 60292 | K33: 126407 | L33: 433760 | M33: 0 | N33: 0 | O33: 0 | P33: 620459 | Q33: 1213017 | R33: 0 | S33: 1213017
A34: 会議費 | B34: =VLOOKUP(A34,Sheet1!$A$1:$B$242,2,FALSE) -> 회의비 | C34: 105451 | D34: 53153 | E34: 128458 | F34: 173989 | G34: 175839 | H34: 111624 | I34: 748514 | J34: 122400 | K34: 224884 | L34: 404363 | M34: 0 | N34: 0 | O34: 0 | P34: 751647 | Q34: 1500161 | R34: 0 | S34: 1500161
A35: 旅費交通費 | B35: =VLOOKUP(A35,Sheet1!$A$1:$B$242,2,FALSE) -> 여비교통비 | C35: 102341 | D35: 123173 | E35: 188819 | F35: 234414 | G35: 175552 | H35: 248471 | I35: 1072770 | J35: 230313 | K35: 1248449 | L35: 2749730 | M35: 0 | N35: 0 | O35: 0 | P35: 4228492 | Q35: 5301262 | R35: 0 | S35: 5301262
... A53: 営業損益金額 | B53: =VLOOKUP(A53,Sheet1!$A$1:$B$242,2,FALSE) -> 영업손익금액 | C53: 1490216 | D53: 3016360 | E53: 10064647 | F53: 5475659 | G53: 2498617 | H53: 11240370 | I53: 33785869 | J53: 11630331 | K53: 7607757 | L53: 36954409 | M53: 0 | N53: 0 | O53: 0 | P53: 56192497 | Q53: 89978366 | R53: 0 | S53: 89978366
A54: [営業外収益] | B54: =VLOOKUP(A54,Sheet1!$A$1:$B$242,2,FALSE) -> [영업외수익]
A56: 受取利息 | B56: =VLOOKUP(A56,Sheet1!$A$1:$B$242,2,FALSE) -> 이자수익 | C56: 0 | D56: 0 | E56: 0 | F56: 0 | G56: 8043 | H56: 0 | I56: 8043 | J56: 0 | K56: 0 | L56: 0 | M56: 0 | N56: 0 | O56: 0 | P56: 0 | Q56: 8043 | R56: 0 | S56: 8043
A57: 貸倒引当金戻入額 | B57: =VLOOKUP(A57,Sheet1!$A$1:$B$242,2,FALSE) -> 대손충당금 환입액 | C57: 0 | D57: 0 | E57: 0 | F57: 0 | G57: 0 | H57: 0 | I57: 0 | J57: 0 | K57: 0 | L57: 206241 | M57: 0 | N57: 0 | O57: 0 | P57: 206241 | Q57: 206241 | R57: 0 | S57: 206241
A58: 雑収入 | B58: =VLOOKUP(A58,Sheet1!$A$1:$B$242,2,FALSE) -> 잡수익 | C58: 113037 | D58: 569628 | E58: 106430 | F58: 681367 | G58: -360545 | H58: 176120 | I58: 1286037 | J58: 333123 | K58: 235671 | L58: 39944 | M58: 0 | N58: 0 | O58: 0 | P58: 608738 | Q58: 1894775 | R58: 0 | S58: 1894775
A59: 営業外収益合計 | B59: =VLOOKUP(A59,Sheet1!$A$1:$B$242,2,FALSE) -> 영업외수익합계 | C59: 113037 | D59: 569628 | E59: 106430 | F59: 681367 | G59: -352502 | H59: 176120 | I59: 1294080 | J59: 333123 | K59: 235671 | L59: 246185 | M59: 0 | N59: 0 | O59: 0 | P59: 814979 | Q59: 2109059 | R59: 0 | S59: 2109059
A60: [営業外費用] | B60: =VLOOKUP(A60,Sheet1!$A$1:$B$242,2,FALSE) -> [영업외비용]
...

Sheet Sheet1
A1: 勘定科目 | B1: 계정과목
A2: 相手勘定科目 | B2: 상대계정과목
A3: 諸口 | B3: 제좌
A4: [現金･預金] | B4: [현금･예금]
A5: 現金 | B5: 현금
A6: 普通預金 | B6: 보통예금
A7: 現金･預金合計 | B7: 현금 ･예금합계
A8: [売上債権] | B8: [매출채권]
A9: 売掛金 | B9: 외상매출금
A10: 売上債権合計 | B10: 매출채권합계
A11: [有価証券] | B11: [유가증권]
A12: 有価証券合計 | B12: 유가증권합계
... A168: 貸倒引当金繰入額(販) | B168: 대손충당금 설정액
